Workbook

Sheet PR CREATE IT 2025
D1: PR CREATE BY IT TAHUN 2025
D3: NO | E3: SEQ | F3: KODE MATERIAL | G3: NAMA MATERIAL | H3: NO. PR | I3: NO. PO | J3: QTY | K3: UNIT | L3: CREATE DATE | M3: STATUS REALEASE | N3: GR DATE | O3: KETERANGAN
A4: =F4&H4&E4 -> 5000016255108000021 | B4: =F4&I4&E4 -> 5000016255797001611 | C4: =F4&I4 -> 500001625579700161 | D4: 1 | E4: ='PR 2025'!A2 -> 1 | F4: ='PR 2025'!B2 -> 5000016255 | G4: ='PR 2025'!C2 -> SSD SATA 256GB | H4: ='PR 2025'!D2 -> 10800002 | I4: =VLOOKUP(A4,'PO 2025'!$A$2:$Y$1440,21,FALSE) -> 79700161 | J4: ='PR 2025'!E2 -> 2 | K4: ='PR 2025'!F2 -> BH | L4: ='PR 2025'!T2 -> 45659 | M4: ='PR 2025'!AG2 -> R | N4: =VLOOKUP(C4,'GRS 2025'!$A$2:$AH$1992,4,FALSE) -> 45674 | O4: ='PR 2025'!AJ2 -> U/ BAGIAN TRAINING & DEVELOPMENT (HS CODE : 8471.50.90). ERDI
A5: =F5&H5&E5 -> 5000011448108000022 | B5: =F5&I5&E5 -> 5000011448797001662 | C5: =F5&I5 -> 500001144879700166 | D5: 2 | E5: ='PR 2025'!A3 -> 2 | F5: ='PR 2025'!B3 -> 5000011448 | G5: ='PR 2025'!C3 -> CABLE USB FOR PRINTER | H5: ='PR 2025'!D3 -> 10800002 | I5: =VLOOKUP(A5,'PO 2025'!$A$2:$Y$1440,21,FALSE) -> 79700166 | J5: ='PR 2025'!E3 -> 2 | K5: ='PR 2025'!F3 -> UNT | L5: ='PR 2025'!T3 -> 45659 | M5: ='PR 2025'!AG3 -> R | N5: =VLOOKUP(C5,'GRS 2025'!$A$2:$AH$1992,4,FALSE) -> 45667 | O5: ='PR 2025'!AJ3 -> URGENT : ORDER YG 3 METER U/ S. MANAGER PRODUKSI, TEKNIK & HRD DAN PEMBELIAN (HS CODE : 8544.20.31). IDRUS
A6: =F6&H6&E6 -> 5000008929108000321 | B6: =F6&I6&E6 -> 5000008929797001661 | C6: =F6&I6 -> 500000892979700166 | D6: 3 | E6: ='PR 2025'!A4 -> 1 | F6: ='PR 2025'!B4 -> 5000008929 | G6: ='PR 2025'!C4 -> FAN PROCESSOR P4 LGA | H6: ='PR 2025'!D4 -> 10800032 | I6: =VLOOKUP(A6,'PO 2025'!$A$2:$Y$1440,21,FALSE) -> 79700166 | J6: ='PR 2025'!E4 -> 6 | K6: ='PR 2025'!F4 -> BH | L6: ='PR 2025'!T4 -> 45660 | M6: ='PR 2025'!AG4 -> R | N6: =VLOOKUP(C6,'GRS 2025'!$A$2:$AH$1992,4,FALSE) -> 45667 | O6: ='PR 2025'!AJ4 -> U/ BAGIAN IT (3), FINAL LJ2, GD PACKING, PPC PROCESSING LJ1 (HS CODE : 8414.59.10). ERDI
A7: =F7&H7&E7 -> 5000011754108000322 | B7: =F7&I7&E7 -> 5000011754797001632 | C7: =F7&I7 -> 500001175479700163 | D7: 4 | E7: ='PR 2025'!A5 -> 2 | F7: ='PR 2025'!B5 -> 5000011754 | G7: ='PR 2025'!C5 -> MOUSE PAD | H7: ='PR 2025'!D5 -> 10800032 | I7: =VLOOKUP(A7,'PO 2025'!$A$2:$Y$1440,21,FALSE) -> 79700163 | J7: ='PR 2025'!E5 -> 1 | K7: ='PR 2025'!F5 -> BH | L7: ='PR 2025'!T5 -> 45660 | M7: ='PR 2025'!AG5 -> R | N7: =VLOOKUP(C7,'GRS 2025'!$A$2:$AH$1992,4,FALSE) -> 45670 | O7: ='PR 2025'!AJ5 -> U/ S. MANAGER PRODUKSI, TEKNIK & HRD (HS CODE : 8471.60.40). DETA
A8: =F8&H8&E8 -> 5000016308108000621 | B8: =F8&I8&E8 -> 5000016308797003631 | C8: =F8&I8 -> 500001630879700363 | D8: 5 | E8: ='PR 2025'!A6 -> 1 | F8: ='PR 2025'!B6 -> 5000016308 | G8: ='PR 2025'!C6 -> CPU BUILDUP | H8: ='PR 2025'!D6 -> 10800062 | I8: =VLOOKUP(A8,'PO 2025'!$A$2:$Y$1440,21,FALSE) -> 79700363 | J8: ='PR 2025'!E6 -> 4 | K8: ='PR 2025'!F6 -> UNT | L8: ='PR 2025'!T6 -> 45661 | M8: ='PR 2025'!AG6 -> R | N8: =VLOOKUP(C8,'GRS 2025'!$A$2:$AH$1992,4,FALSE) -> 45674 | O8: ='PR 2025'!AJ6 -> U/ PROGRAM APLIKASI BARU GD GREY LJ1 & LJ2 (HS CODE : 8479.89.50). AGUS
A9: =F9&H9&E9 -> 5000016255108000622 | B9: =F9&I9&E9 -> 5000016255797003632 | C9: =F9&I9 -> 500001625579700363 | D9: 6 | E9: ='PR 2025'!A7 -> 2 | F9: ='PR 2025'!B7 -> 5000016255 | G9: ='PR 2025'!C7 -> SSD SATA 256GB | H9: ='PR 2025'!D7 -> 10800062 | I9: =VLOOKUP(A9,'PO 2025'!$A$2:$Y$1440,21,FALSE) -> 79700363 | J9: ='PR 2025'!E7 -> 4 | K9: ='PR 2025'!F7 -> BH | L9: ='PR 2025'!T7 -> 45661 | M9: ='PR 2025'!AG7 -> R | N9: =VLOOKUP(C9,'GRS 2025'!$A$2:$AH$1992,4,FALSE) -> 45674 | O9: ='PR 2025'!AJ7 -> U/ PROGRAM APLIKASI BARU GD GREY LJ1 & LJ2 (HS CODE : 8471.50.90). AGUS
A10: =F10&H10&E10 -> 5000016728108000971 | B10: =F10&I10&E10 -> 5000016728797008031 | C10: =F10&I10 -> 500001672879700803 | D10: 7 | E10: ='PR 2025'!A8 -> 1 | F10: ='PR 2025'!B8 -> 5000016728 | G10: ='PR 2025'!C8 -> SWITCH D-LINK 8 PORT | H10: ='PR 2025'!D8 -> 10800097 | I10: =VLOOKUP(A10,'PO 2025'!$A$2:$Y$1440,21,FALSE) -> 79700803 | J10: ='PR 2025'!E8 -> 1 | K10: ='PR 2025'!F8 -> UNT | L10: ='PR 2025'!T8 -> 45664 | M10: ='PR 2025'!AG8 -> R | N10: =VLOOKUP(C10,'GRS 2025'!$A$2:$AH$1992,4,FALSE) -> 45684 | O10: ='PR 2025'!AJ8 -> U/ MTC PERSIAPAN LJ2 (HS CODE : 8517.79.10). TIO
A11: =F11&H11&E11 -> 5000017356108001391 | B11: =F11&I11&E11 -> 5000017356797007881 | C11: =F11&I11 -> 500001735679700788 | D11: 8 | E11: ='PR 2025'!A9 -> 1 | F11: ='PR 2025'!B9 -> 5000017356 | G11: ='PR 2025'!C9 -> PROYEKTOR BENQ MX631ST | H11: ='PR 2025'!D9 -> 10800139 | I11: =VLOOKUP(A11,'PO 2025'!$A$2:$Y$1440,21,FALSE) -> 79700788 | J11: ='PR 2025'!E9 -> 1 | K11: ='PR 2025'!F9 -> UNT | L11: ='PR 2025'!T9 -> 45666 | M11: ='PR 2025'!AG9 -> R | N11: =VLOOKUP(C11,'GRS 2025'!$A$2:$AH$1992,4,FALSE) -> 45687 | O11: ='PR 2025'!AJ9 -> U/ RUANG MEETING BAGIAN DF LJ1 (HS CODE : 9007.92.00). ERISA
A12: =F12&H12&E12 -> 5000008843108001392 | B12: =F12&I12&E12 -> 5000008843797008022 | C12: =F12&I12 -> 500000884379700802 | D12: 9 | E12: ='PR 2025'!A10 -> 2 | F12: ='PR 2025'!B10 -> 5000008843 | G12: ='PR 2025'!C10 -> MONITOR LCD 19 INCH | H12: ='PR 2025'!D10 -> 10800139 | I12: =VLOOKUP(A12,'PO 2025'!$A$2:$Y$1440,21,FALSE) -> 79700802 | J12: ='PR 2025'!E10 -> 1 | K12: ='PR 2025'!F10 -> UNT | L12: ='PR 2025'!T10 -> 45666 | M12: ='PR 2025'!AG10 -> R | N12: =VLOOKUP(C12,'GRS 2025'!$A$2:$AH$1992,4,FALSE) -> 45685 | O12: ='PR 2025'!AJ10 -> U/ RUANG MEETING BAGIAN DF LJ1 (HS CODE : 8528.52.00). ERISA
A13: =F13&H13&E13 -> 5000016308108001393 | B13: =F13&I13&E13 -> 5000016308797007883 | C13: =F13&I13 -> 500001630879700788 | D13: 10 | E13: ='PR 2025'!A11 -> 3 | F13: ='PR 2025'!B11 -> 5000016308 | G13: ='PR 2025'!C11 -> CPU BUILDUP | H13: ='PR 2025'!D11 -> 10800139 | I13: =VLOOKUP(A13,'PO 2025'!$A$2:$Y$1440,21,FALSE) -> 79700788 | J13: ='PR 2025'!E11 -> 1 | K13: ='PR 2025'!F11 -> UNT | L13: ='PR 2025'!T11 -> 45666 | M13: ='PR 2025'!AG11 -> R | N13: =VLOOKUP(C13,'GRS 2025'!$A$2:$AH$1992,4,FALSE) -> 45687 | O13: ='PR 2025'!AJ11 -> U/ RUANG MEETING BAGIAN DF LJ1 (HS CODE : 8479.89.50). ERISA
A14: =F14&H14&E14 -> 5000005059108001394 | B14: =F14&I14&E14 -> 5000005059797006794 | C14: =F14&I14 -> 500000505979700679 | D14: 11 | E14: ='PR 2025'!A12 -> 4 | F14: ='PR 2025'!B12 -> 5000005059 | G14: ='PR 2025'!C12 -> KEYBOARD USB | H14: ='PR 2025'!D12 -> 10800139 | I14: =VLOOKUP(A14,'PO 2025'!$A$2:$Y$1440,21,FALSE) -> 79700679 | J14: ='PR 2025'!E12 -> 1 | K14: ='PR 2025'!F12 -> BH | L14: ='PR 2025'!T12 -> 45666 | M14: ='PR 2025'!AG12 -> R | N14: =VLOOKUP(C14,'GRS 2025'!$A$2:$AH$1992,4,FALSE) -> 45688 | O14: ='PR 2025'!AJ12 -> U/ RUANG MEETING BAGIAN DF LJ1 (HS CODE : 8471.60.30). ERISA
A15: =F15&H15&E15 -> 5000004248108001395 | B15: =F15&I15&E15 -> 5000004248797006795 | C15: =F15&I15 -> 500000424879700679 | D15: 12 | E15: ='PR 2025'!A13 -> 5 | F15: ='PR 2025'!B13 -> 5000004248 | G15: ='PR 2025'!C13 -> MOUSE USB | H15: ='PR 2025'!D13 -> 10800139 | I15: =VLOOKUP(A15,'PO 2025'!$A$2:$Y$1440,21,FALSE) -> 79700679 | J15: ='PR 2025'!E13 -> 1 | K15: ='PR 2025'!F13 -> BH | L15: ='PR 2025'!T13 -> 45666 | M15: ='PR 2025'!AG13 -> R | N15: =VLOOKUP(C15,'GRS 2025'!$A$2:$AH$1992,4,FALSE) -> 45688 | O15: ='PR 2025'!AJ13 -> U/ RUANG MEETING BAGIAN DF LJ1 (HS CODE : 8471.60.40). ERISA
... A464: =F464&H464&E464 -> 5000018023108056241 | B464: =F464&I464&E464 -> #N/A | C464: =F464&I464 -> #N/A | D464: 461 | E464: ='PR 2025'!A462 -> 1 | F464: ='PR 2025'!B462 -> 5000018023 | G464: ='PR 2025'!C462 -> PENGUAT SINYAL GSM | H464: ='PR 2025'!D462 -> 10805624 | I464: =VLOOKUP(A464,'PO 2025'!$A$2:$Y$1440,21,FALSE) -> #N/A | J464: ='PR 2025'!E462 -> 1 | K464: ='PR 2025'!F462 -> BH | L464: ='PR 2025'!T462 -> 45993 | M464: ='PR 2025'!AG462 -> R | N464: =VLOOKUP(C464,'GRS 2025'!$A$2:$AH$1992,4,FALSE) -> #N/A | O464: ='PR 2025'!AJ462 -> U/ KANTOR PROCESSING LJ1 (HS CODE : 8517.79.10). DADANG
G488: KET. | I488: PR SUDAH JADI PO/BARANG BELUM DATANG
I489: PR BELUM RELEASE BAGIAN IT
I490: PR BELUM JADI PO SAMA PEMBELIAN
I491: REJECT
I492: PR KADALUWARSA (TIDAK AKAN BISA DIBUAT PO)

Sheet PR 2025
A1: SEQ | B1: ITEM_CODE | C1: ITEM_DESC | D1: PRH_CODE | E1: QTY | F1: UNIT | G1: DEL_DATE | H1: ITEM_GROUP | I1: PLANT | J1: SLOC | K1: PCGROUP | L1: PCORG | M1: STATUS | N1: VEN_MAT_NAME | O1: BATCH | P1: QTY_OPEN | Q1: QTY_ORDER | R1: TOTAL | S1: CREATE_BY | T1: CREATE_DATE | U1: MODIFY_BY | V1: MODIFY_DATE | W1: PRI_INDICATOR | X1: TLP | Y1: PLAN_NAME | Z1: ADDRESS | AA1: CITY | AB1: COUNTRY | AC1: GLACC | AD1: MO_CODE | AE1: COST_CENTER | AF1: CAT | AG1: REL_STATUS | AH1: VAL_TYPE | AI1: REQUISITIONER | AJ1: COMMENTS | AK1: SERIAL_NUMBER
A2: 1 | B2: 5000016255 | C2: SSD SATA 256GB | D2: 10800002 | E2: 2 | F2: BH | G2: 45666 | H2: INVT-COMP | I2: LJU | J2: LJIV | K2: LI03 | L2: POLU | M2: 0 | P2: 2 | Q2: 0 | S2: A_TI | T2: 45659 | W2: 1 | Y2: PT LEUWITEX | AG2: R | AJ2: U/ BAGIAN TRAINING & DEVELOPMENT (HS CODE : 8471.50.90). ERDI
A3: 2 | B3: 5000011448 | C3: CABLE USB FOR PRINTER | D3: 10800002 | E3: 2 | F3: UNT | G3: 45666 | H3: INVT-COMP | I3: LJU | J3: LJIV | K3: LI03 | L3: POLU | M3: 0 | P3: 2 | Q3: 0 | S3: A_TI | T3: 45659 | W3: 1 | Y3: PT LEUWITEX | AG3: R | AJ3: URGENT : ORDER YG 3 METER U/ S. MANAGER PRODUKSI, TEKNIK & HRD DAN PEMBELIAN (HS CODE : 8544.20.31). IDRUS
A4: 1 | B4: 5000008929 | C4: FAN PROCESSOR P4 LGA | D4: 10800032 | E4: 6 | F4: BH | G4: 45667 | H4: INVT-COMP | I4: LJU | J4: LJIV | K4: LI03 | L4: POLU | M4: 0 | P4: 6 | Q4: 0 | S4: A_TI | T4: 45660 | W4: 1 | Y4: PT LEUWITEX | AG4: R | AJ4: U/ BAGIAN IT (3), FINAL LJ2, GD PACKING, PPC PROCESSING LJ1 (HS CODE : 8414.59.10). ERDI
A5: 2 | B5: 5000011754 | C5: MOUSE PAD | D5: 10800032 | E5: 1 | F5: BH | G5: 45664 | H5: INVT-COMP | I5: LJU | J5: LJIV | K5: LI03 | L5: POLU | M5: 0 | P5: 1 | Q5: 0 | S5: A_TI | T5: 45660 | W5: 1 | Y5: PT LEUWITEX | AG5: R | AJ5: U/ S. MANAGER PRODUKSI, TEKNIK & HRD (HS CODE : 8471.60.40). DETA
A6: 1 | B6: 5000016308 | C6: CPU BUILDUP | D6: 10800062 | E6: 4 | F6: UNT | G6: 45668 | H6: INVT-COMP | I6: LJU | J6: LJIV | K6: LI03 | L6: POLU | M6: 1 | P6: -4 | Q6: 8 | S6: A_TI | T6: 45661 | W6: 1 | Y6: PT LEUWITEX | AG6: R | AJ6: U/ PROGRAM APLIKASI BARU GD GREY LJ1 & LJ2 (HS CODE : 8479.89.50). AGUS
A7: 2 | B7: 5000016255 | C7: SSD SATA 256GB | D7: 10800062 | E7: 4 | F7: BH | G7: 45668 | H7: INVT-COMP | I7: LJU | J7: LJIV | K7: LI03 | L7: POLU | M7: 1 | P7: -4 | Q7: 8 | S7: A_TI | T7: 45661 | W7: 1 | Y7: PT LEUWITEX | AG7: R | AJ7: U/ PROGRAM APLIKASI BARU GD GREY LJ1 & LJ2 (HS CODE : 8471.50.90). AGUS
A8: 1 | B8: 5000016728 | C8: SWITCH D-LINK 8 PORT | D8: 10800097 | E8: 1 | F8: UNT | G8: 45671 | H8: INVT-COMP | I8: LJU | J8: LJIV | K8: LI03 | L8: POLU | M8: 0 | P8: 1 | Q8: 0 | S8: A_TI | T8: 45664 | W8: 1 | Y8: PT LEUWITEX | AG8: R | AJ8: U/ MTC PERSIAPAN LJ2 (HS CODE : 8517.79.10). TIO
A9: 1 | B9: 5000017356 | C9: PROYEKTOR BENQ MX631ST | D9: 10800139 | E9: 1 | F9: UNT | G9: 45673 | H9: INVT-COMP | I9: LJU | J9: LJIV | K9: LI03 | L9: POLU | M9: 0 | P9: 1 | Q9: 0 | S9: A_TI | T9: 45666 | W9: 1 | Y9: PT LEUWITEX | AG9: R | AJ9: U/ RUANG MEETING BAGIAN DF LJ1 (HS CODE : 9007.92.00). ERISA
A10: 2 | B10: 5000008843 | C10: MONITOR LCD 19 INCH | D10: 10800139 | E10: 1 | F10: UNT | G10: 45673 | H10: INVT-COMP | I10: LJU | J10: LJIV | K10: LI03 | L10: POLU | M10: 0 | P10: 1 | Q10: 0 | S10: A_TI | T10: 45666 | W10: 1 | Y10: PT LEUWITEX | AG10: R | AJ10: U/ RUANG MEETING BAGIAN DF LJ1 (HS CODE : 8528.52.00). ERISA
A11: 3 | B11: 5000016308 | C11: CPU BUILDUP | D11: 10800139 | E11: 1 | F11: UNT | G11: 45673 | H11: INVT-COMP | I11: LJU | J11: LJIV | K11: LI03 | L11: POLU | M11: 0 | P11: 1 | Q11: 0 | S11: A_TI | T11: 45666 | W11: 1 | Y11: PT LEUWITEX | AG11: R | AJ11: U/ RUANG MEETING BAGIAN DF LJ1 (HS CODE : 8479.89.50). ERISA
A12: 4 | B12: 5000005059 | C12: KEYBOARD USB | D12: 10800139 | E12: 1 | F12: BH | G12: 45673 | H12: INVT-COMP | I12: LJU | J12: LJIV | K12: LI03 | L12: POLU | M12: 0 | P12: 1 | Q12: 0 | S12: A_TI | T12: 45666 | W12: 1 | Y12: PT LEUWITEX | AG12: R | AJ12: U/ RUANG MEETING BAGIAN DF LJ1 (HS CODE : 8471.60.30). ERISA
A13: 5 | B13: 5000004248 | C13: MOUSE USB | D13: 10800139 | E13: 1 | F13: BH | G13: 45673 | H13: INVT-COMP | I13: LJU | J13: LJIV | K13: LI03 | L13: POLU | M13: 0 | P13: 1 | Q13: 0 | S13: A_TI | T13: 45666 | W13: 1 | Y13: PT LEUWITEX | AG13: R | AJ13: U/ RUANG MEETING BAGIAN DF LJ1 (HS CODE : 8471.60.40). ERISA
... A84: 4 | B84: 5000005059 | C84: KEYBOARD USB | D84: 10800880 | E84: 10 | F84: BH | G84: 45715 | H84: INVT-COMP | I84: LJU | J84: LJIV | K84: LI03 | L84: POLU | M84: 0 | P84: 10 | Q84: 0 | S84: A_TI | T84: 45708 | W84: 1 | Y84: PT LEUWITEX | AG84: R | AJ84: U/ MENGGANTI YG RUSAK BAGIAN PERSIAPAN LUCKYTEX, QA (2), RND, PROCCESSING DF (2), GUDANG GREY,GUDANG BENANG, MTC WEAVING DAN PPC GREY (HS CODE : 8471.60.30). ALI
A85: 1 | B85: 5000017677 | C85: HTB 1100S | D85: 10800909 | E85: 3 | F85: SET | G85: 45717 | H85: INVT-COMP | I85: LJU | J85: LJIV | K85: LI03 | L85: POLU | M85: 0 | P85: 3 | Q85: 0 | S85: A_TI | T85: 45710 | U85: A_TI | V85: 45710 | W85: 1 | Y85: PT LEUWITEX | AG85: R | AJ85: U/ AREA IPAL (HS CODE : 8454.10.00). TIO
A86: 2 | B86: 5000016779 | C86: SWITCH D-LINK 16 PORT | D86: 10800909 | E86: 1 | F86: UNT | G86: 45717 | H86: INVT-COMP | I86: LJU | J86: LJIV | K86: LI03 | L86: POLU | M86: 0 | P86: 1 | Q86: 0 | S86: A_TI | T86: 45710 | W86: 1 | Y86: PT LEUWITEX | AG86: R | AJ86: U/ AREA IPAL (HS CODE : 8517.79.10). TIO
A87: 3 | B87: 5000017676 | C87: PATCH CORD SC TO SC | D87: 10800909 | E87: 3 | F87: BH | G87: 45717 | H87: INVT-COMP | I87: LJU | J87: LJIV | K87: LI03 | L87: POLU | M87: 0 | P87: 3 | Q87: 0 | S87: A_TI | T87: 45710 | W87: 1 | Y87: PT LEUWITEX | AG87: R | AJ87: U/ AREA IPAL (HS CODE : 8544.49.49). TIO
A88: 1 | B88: 5000016585 | C88: KABEL POWER PRINTER | D88: 10800926 | E88: 1 | F88: UNT | G88: 45719 | H88: INVT-COMP | I88: LJU | J88: LJIV | K88: LI03 | L88: POLU | M88: 0 | P88: 1 | Q88: 0 | S88: A_TI | T88: 45712 | W88: 1 | Y88: PT LEUWITEX | AG88: R | AJ88: U/ BAGIAN MACHCRIMPER (HS CODE : 8544.20.31). TIO
A89: 1 | B89: 5000016375 | C89: PRINTER EPSON l3210 | D89: 10800953 | E89: 1 | F89: UNT | G89: 45720 | H89: INVT-COMP | I89: LJU | J89: LJIV | K89: LI03 | L89: POLU | M89: 0 | P89: 1 | Q89: 0 | S89: A_TI | T89: 45713 | W89: 1 | Y89: PT LEUWITEX | AG89: R | AJ89: URGENT : U/ MENGGANTI YANG RUSAK BAGIAN BEA CUKAI. (HS CODE : 8443.31.11). PUTRI
A90: 2 | B90: 5000017376 | C90: RAM DDR4 8 GB | D90: 10800953 | E90: 1 | F90: BH | G90: 45720 | H90: INVT-COMP | I90: LJU | J90: LJIV | K90: LI03 | L90: POLU | M90: 0 | P90: 1 | Q90: 0 | S90: A_TI | T90: 45713 | W90: 1 | Y90: PT LEUWITEX | AG90: R | AJ90: MEMORY RAM SERVER ECC 8GB PC4-2133P, U/ BAGIAN IT (HS CODE : 8471.50.90). ERDI
A91: 1 | B91: 5000015560 | C91: RAM DDR3 8GB | D91: 10801030 | E91: 2 | F91: BH | G91: 45724 | H91: INVT-COMP | I91: LJU | J91: LJIV | K91: LI03 | L91: POLU | M91: 0 | P91: 2 | Q91: 0 | S91: A_TI | T91: 45717 | W91: 1 | Y91: PT LEUWITEX | AG91: R | AJ91: U/ BAGIAN IT (HS CODE : 8471.50.90). ERDI
A92: 2 | B92: 5000017695 | C92: PRINTER EPSON L18050 | D92: 10801030 | E92: 1 | F92: UNT | G92: 45724 | H92: INVT-COMP | I92: LJU | J92: LJIV | K92: LI03 | L92: POLU | M92: 0 | P92: 1 | Q92: 0 | S92: A_TI | T92: 45717 | W92: 1 | Y92: PT LEUWITEX | AG92: R | AJ92: U/ MENGGANTI YANG RUSAK BAGIAN TRAINING & DEVELOPMENT (HS CODE : 8443.31.11). FIRMAN
A93: 3 | B93: 5000017481 | C93: SCANNER PLUSTEK PS283 | D93: 10801030 | E93: 1 | F93: UNT | G93: 45724 | H93: INVT-COMP | I93: LJU | J93: LJIV | K93: LI03 | L93: POLU | M93: 0 | P93: 1 | Q93: 0 | S93: A_TI | T93: 45717 | W93: 1 | Y93: PT LEUWITEX | AG93: R | AJ93: U/ MENGGANTI YANG RUSAK BAGIAN TRAINING & DEVELOPMENT (HS CODE : 8443.31.91). FIRMAN
A94: 4 | B94: 5000016583 | C94: CPU BUILDUP I7 | D94: 10801030 | E94: 1 | F94: UNT | G94: 45724 | H94: INVT-COMP | I94: LJU | J94: LJIV | K94: L04 | L94: POLU | M94: 0 | P94: 1 | Q94: 0 | S94: A_TI | T94: 45719 | W94: 1 | Y94: PT LEUWITEX | AG94: R | AJ94: URGENT : U/ BAGIAN MARKETING (HS CODE : 8479.89.50). YUANITA
A95: 5 | B95: 5000005340 | C95: POWER SUPLY ATX 450 WATT | D95: 10801030 | E95: 1 | F95: UNT | G95: 45724 | H95: INVT-COMP | I95: LJU | J95: LJIV | K95: LI03 | L95: POLU | M95: 0 | P95: 1 | Q95: 0 | S95: A_TI | T95: 45719 | W95: 1 | Y95: PT LEUWITEX | AG95: R | AJ95: U/ MENGGANTI YG RUSAK BAGIAN MARKETING (HS CODE : 8414.59.10). TIO
A96: 6 | B96: 5000016659 | C96: COOLER MASTER | D96: 10801030 | E96: 2 | F96: BH | G96: 45727 | H96: INVT-COMP | I96: LJU | J96: LJIV | K96: LI03 | L96: POLU | M96: 0 | P96: 2 | Q96: 0 | S96: A_TI | T96: 45720 | W96: 1 | Y96: PT LEUWITEX | AG96: R | AJ96: U/ MENGGANTI YG RUSAK BAGIAN MTC PROC LJ1 DAN LAB (HS CODE : 8414.59.10). RICKY
A97: 7 | B97: 5000012006 | C97: MONITOR TV 32 INCH | D97: 10801030 | E97: 1 | F97: UNT | G97: 45727 | H97: INVT-COMP | I97: LJU | J97: LJIV | K97: LI03 | L97: POLU | M97: 0 | P97: 1 | Q97: 0 | S97: A_TI | T97: 45720 | W97: 1 | Y97: PT LEUWITEX | AG97: R | AJ97: URGENT : U/ MENGGANTI YG RUSAK (MONITORING CCTV AREA BEA CUKAI) (HS CODE : 8528.52.00). TIO
... A108: 1 | B108: 5000016930 | C108: PRINT SERVER | D108: 10801283 | E108: 2 | F108: BH | G108: 45740 | H108: INVT-COMP | I108: LJU | J108: LJIV | K108: LI03 | L108: POLU | M108: 0 | P108: 2 | Q108: 0 | S108: A_TI | T108: 45733 | W108: 1 | Y108: PT LEUWITEX | AG108: R | AJ108: U/ BAGIAN PPC PROCESSING LJ1 DAN TRAINING & DEV (HS CODE : 8517.79.10). TIO
A109: 2 | B109: 5000000739 | C109: KABEL UTP BELDEN | D109: 10801283 | E109: 4 | F109: ROL | G109: 45741 | H109: INVT-COMP | I109: LJU | J109: LJIV | K109: LI03 | L109: POLU | M109: 1 | P109: 0 | Q109: 4 | S109: A_TI | T109: 45734 | U109: A_TI | V109: 45735 | W109: 1 | Y109: PT LEUWITEX | AG109: R | AJ109: U/ PROYEK PERSONALIA, GA DAN RND. (HS CODE : 8517.14.00). TIO
A110: 3 | B110: 5000016554 | C110: KARTU RFID | D110: 10801283 | E110: 400 | F110: BH | G110: 45742 | H110: INVT-COMP | I110: LJU | J110: LJIV | K110: LI03 | L110: POLU | M110: 0 | P110: 400 | Q110: 0 | S110: A_TI | T110: 45735 | U110: A_TI | V110: 45735 | W110: 1 | Y110: PT LEUWITEX | AG110: R | AJ110: U/ BAGIAN PERSONALIA (HS CODE : 8523.59.10). ERIK
A111: 1 | B111: 5000000739 | C111: KABEL UTP BELDEN | D111: 10801338 | E111: 3 | F111: ROL | G111: 45742 | H111: INVT-COMP | I111: LJU | J111: LJIV | K111: LI03 | L111: POLU | M111: 1 | P111: 0 | Q111: 3 | S111: A_TI | T111: 45735 | W111: 1 | Y111: PT LEUWITEX | AG111: R | AJ111: URGENT : U/ AREA GD BENANG, GD OBAT & GD BEKAS. (HS CODE : 8517.14.00) ERDI
A112: 2 | B112: 5000000740 | C112: CONECTOR RJ 45 | D112: 10801338 | E112: 100 | F112: BH | G112: 45742 | H112: INVT-COMP | I112: LJU | J112: LJIV | K112: LI03 | L112: POLU | M112: 1 | P112: 99 | Q112: 1 | S112: A_TI | T112: 45735 | W112: 1 | Y112: PT LEUWITEX | AG112: R | AJ112: URGENT : U/ BAGIAN IT. (HS CODE : 8536.70.90) ERDI
A113: 3 | B113: 5000014668 | C113: NVR 16CH DAHUA 4216 | D113: 10801338 | E113: 1 | F113: UNT | G113: 45742 | H113: INVT-COMP | I113: LJU | J113: LJIV | K113: LI03 | L113: POLU | M113: 1 | P113: 0 | Q113: 1 | S113: A_TI | T113: 45735 | W113: 1 | Y113: PT LEUWITEX | AG113: R | AJ113: URGENT : U/ S. MGR. PRODUKSI, TEKNIK, ADMIN & HRD (BPK ZENZEN). (HS CODE : 8521.90.99) ERDI
A114: 4 | B114: 5000015833 | C114: HARDISK 8 TB WD PURPLE | D114: 10801338 | E114: 1 | F114: UNT | G114: 45742 | H114: INVT-COMP | I114: LJU | J114: LJIV | K114: LI03 | L114: POLU | M114: 1 | P114: 0 | Q114: 1 | S114: A_TI | T114: 45735 | W114: 1 | Y114: PT LEUWITEX | AG114: R | AJ114: URGENT : U/ S. MGR. PRODUKSI, TEKNIK, ADMIN & HRD (BPK ZENZEN). (HS CODE : 8471.50.90) ERDI
A115: 1 | B115: 5000016541 | C115: FLASH DISK 16 GB | D115: 10801342 | E115: 2 | F115: BH | G115: 45743 | H115: INVT-COMP | I115: LJU | J115: LJIV | K115: LI03 | L115: POLU | M115: 0 | P115: 2 | Q115: 0 | S115: A_TI | T115: 45736 | W115: 1 | Y115: PT LEUWITEX | AG115: R | AJ115: U/ BAGIAN GA (HS CODE : 8523.29.71). RISWADI
A116: 2 | B116: 5000015861 | C116: KAMERA WATERPROOF IP 4MP DAHUA POE | D116: 10801342 | E116: 8 | F116: UNT | G116: 45743 | H116: INVT-COMP | I116: LJU | J116: LJIV | K116: LI03 | L116: POLU | M116: 0 | P116: 8 | Q116: 0 | S116: A_TI | T116: 45736 | W116: 1 | Y116: PT LEUWITEX | AG116: R | AJ116: URGENT : PERMINTAAN BPK ZENZEN ADA PENAMBAHAN AREA PERGUDANGAN (HS CODE : 8525.81.10). IDRUS
A117: 3 | B117: 5000015000 | C117: POE INJECTOR | D117: 10801342 | E117: 8 | F117: UNT | G117: 45743 | H117: INVT-COMP | I117: LJU | J117: LJIV | K117: LI03 | L117: POLU | M117: 0 | P117: 8 | Q117: 0 | S117: A_TI | T117: 45736 | W117: 1 | Y117: PT LEUWITEX | AG117: R | AJ117: URGENT : PERMINTAAN BPK ZENZEN ADA PENAMBAHAN AREA PERGUDANGAN (HS CODE : 8517.79.10). IDRUS
A118: 4 | B118: 5000008843 | C118: MONITOR LCD 19 INCH | D118: 10801342 | E118: 1 | F118: UNT | G118: 45743 | H118: INVT-COMP | I118: LJU | J118: LJIV | K118: LI03 | L118: POLU | M118: 0 | P118: 1 | Q118: 0 | S118: A_TI | T118: 45736 | W118: 1 | Y118: PT LEUWITEX | AG118: R | AJ118: U/ ASST. MGR. TEKNIK (HS CODE : 8528.52.00). REYZA
A119: 5 | B119: 5000016308 | C119: CPU BUILDUP | D119: 10801342 | E119: 1 | F119: UNT | G119: 45743 | H119: INVT-COMP | I119: LJU | J119: LJIV | K119: LI03 | L119: POLU | M119: 0 | P119: 1 | Q119: 0 | S119: A_TI | T119: 45736 | W119: 1 | Y119: PT LEUWITEX | AG119: R | AJ119: U/ ASST. MGR. TEKNIK (HS CODE : 8479.89.50). REYZA
A120: 6 | B120: 5000005059 | C120: KEYBOARD USB | D120: 10801342 | E120: 1 | F120: BH | G120: 45743 | H120: INVT-COMP | I120: LJU | J120: LJIV | K120: LI03 | L120: POLU | M120: 0 | P120: 1 | Q120: 0 | S120: A_TI | T120: 45736 | W120: 1 | Y120: PT LEUWITEX | AG120: R | AJ120: U/ ASST. MGR. TEKNIK (HS CODE : 8471.60.30). REYZA
...

Sheet PO 2025
B1: SEQ | C1: PR_CODE | D1: PR_SEQ | E1: ITEM_CODE | F1: ITEM_DESC | G1: PO_QTY | H1: UNIT | I1: DEL_DATE | J1: CAT | K1: NET_PRICE | L1: CURR | M1: MAT_GROUP | N1: PLANT | O1: SLOC | P1: BATCH | Q1: VEN_MAT_NAME | R1: PCGROUP | S1: PCORG | T1: STATUS | U1: POM_CODE | V1: QTY_OPE | W1: QTY_DEL | X1: CREATE_BY | Y1: CREATE_DATE | Z1: MODIFY_BY | AA1: MODIFY_DATE | AB1: GLACC | AC1: TLP | AD1: PLANT_NAME | AE1: P_ADDRESS | AF1: P_CITY | AG1: P_COUNTRY | AH1: MO_CODE | AI1: COST_CENTER | AJ1: INFOREC | AK1: G_WEIGHT | AL1: UNIT_W | AM1: VOLUME | AN1: UNIT_VOL | AO1: OVER_DEL_TOL | AP1: UNDER_DEL_TOL | AQ1: REMINDER | AR1: PLANT_DEL_TIME | AS1: P_ZIP | AT1: P_PROV | AU1: P_TLP | AV1: P_FAX | AW1: P_CONTACT | AX1: DEL_COMP | AY1: COMMENTS | AZ1: PR_SN
B2: 2 | C2: 10800002 | D2: 1 | E2: 5000016255 | F2: SSD SATA 256GB | G2: 2 | H2: BH | I2: 45666 | K2: 343000 | L2: IDR | M2: INVT-COMP | N2: LJU | O2: LJIV | R2: LI03 | S2: POLU | T2: 0 | U2: 79700161 | V2: 2 | W2: 0 | X2: PO_INVT | Y2: 45663 | AD2: PT LEUWITEX | AY2: U/ BAGIAN TRAINING & DEVELOPMENT (HS CODE : 8471.50.90). ERDI
A3: =E3&C3&D3 -> 5000011754108000322 | B3: 1 | C3: 10800032 | D3: 2 | E3: 5000011754 | F3: MOUSE PAD | G3: 1 | H3: BH | I3: 45664 | K3: 20000 | L3: IDR | M3: INVT-COMP | N3: LJU | O3: LJIV | R3: LI03 | S3: POLU | T3: 0 | U3: 79700163 | V3: 0 | W3: 1 | X3: PO_INVT | Y3: 45663 | AD3: PT LEUWITEX | AX3: X | AY3: U/ S. MANAGER PRODUKSI, TEKNIK & HRD (HS CODE : 8471.60.40). DETA
A4: =E4&C4&D4 -> 5000011448108000022 | B4: 3 | C4: 10800002 | D4: 2 | E4: 5000011448 | F4: CABLE USB FOR PRINTER | G4: 2 | H4: UNT | I4: 45666 | K4: 50000 | L4: IDR | M4: INVT-COMP | N4: LJU | O4: LJIV | R4: LI03 | S4: POLU | T4: 0 | U4: 79700166 | V4: 0 | W4: 2 | X4: PO_INVT | Y4: 45663 | AD4: PT LEUWITEX | AX4: X | AY4: URGENT : ORDER YG 3 METER U/ S. MANAGER PRODUKSI, TEKNIK & HRD DAN PEMBELIAN (HS CODE : 8544.20.31). IDRUS
A5: =E5&C5&D5 -> 5000008929108000321 | B5: 4 | C5: 10800032 | D5: 1 | E5: 5000008929 | F5: FAN PROCESSOR P4 LGA | G5: 6 | H5: BH | I5: 45667 | K5: 150000 | L5: IDR | M5: INVT-COMP | N5: LJU | O5: LJIV | R5: LI03 | S5: POLU | T5: 0 | U5: 79700166 | V5: 0 | W5: 6 | X5: PO_INVT | Y5: 45663 | AD5: PT LEUWITEX | AX5: X | AY5: U/ BAGIAN IT (3), FINAL LJU, GD PACKING, PPC PROCESSING LJ1 (HS CODE : 8414.59.10). ERDI
A6: =E6&C6&D6 -> 5000016308108000621 | B6: 1 | C6: 10800062 | D6: 1 | E6: 5000016308 | F6: CPU BUILDUP | G6: 3 | H6: UNT | I6: 45668 | K6: 2980000 | L6: IDR | M6: INVT-COMP | N6: LJU | O6: LJIV | R6: LI03 | S6: POLU | T6: 0 | U6: 79700363 | V6: 3 | W6: 0 | X6: PO_INVT | Y6: 45667 | Z6: PO_INVT | AA6: 45667 | AD6: PT LEUWITEX | AY6: U/ PROGRAM APLIKASI BARU GD GREY LJ1 (I5 GEN 6) (HS CODE : 8479.89.50). AGUS
A7: =E7&C7&D7 -> 5000016255108000622 | B7: 2 | C7: 10800062 | D7: 2 | E7: 5000016255 | F7: SSD SATA 256GB | G7: 2 | H7: BH | I7: 45668 | K7: 343000 | L7: IDR | M7: INVT-COMP | N7: LJU | O7: LJIV | R7: LI03 | S7: POLU | T7: 0 | U7: 79700363 | V7: 2 | W7: 0 | X7: PO_INVT | Y7: 45667 | AD7: PT LEUWITEX | AY7: U/ PROGRAM APLIKASI BARU GD GREY LJ1 (HS CODE : 8479.89.50). AGUS
A8: =E8&C8&D8 -> 5000016308108000621 | B8: 1 | C8: 10800062 | D8: 1 | E8: 5000016308 | F8: CPU BUILDUP | G8: 1 | H8: UNT | I8: 45668 | K8: 2980000 | L8: IDR | M8: INVT-COMP | N8: LJU | O8: LJIV | R8: LI03 | S8: POLU | T8: 0 | U8: 79700364 | V8: 1 | W8: 0 | X8: PO_INVT | Y8: 45667 | Z8: PO_INVT | AA8: 45667 | AD8: PT LEUWITEX | AY8: U/ PROGRAM APLIKASI BARU GD GREY LJ2( I5 GEN 6) (HS CODE : 8479.89.50). AGUS
A9: =E9&C9&D9 -> 5000016255108000622 | B9: 2 | C9: 10800062 | D9: 2 | E9: 5000016255 | F9: SSD SATA 256GB | G9: 2 | H9: BH | I9: 45668 | K9: 343000 | L9: IDR | M9: INVT-COMP | N9: LJU | O9: LJIV | R9: LI03 | S9: POLU | T9: 0 | U9: 79700364 | V9: 2 | W9: 0 | X9: PO_INVT | Y9: 45667 | AD9: PT LEUWITEX | AY9: U/ PROGRAM APLIKASI BARU GD GREY LJ2 (HS CODE : 8479.89.50). AGUS
A10: =E10&C10&D10 -> 5000016255108000021 | B10: 2 | C10: 10800002 | D10: 1 | E10: 5000016255 | F10: SSD SATA 256GB | G10: 2 | H10: BH | I10: 45666 | K10: 343000 | L10: IDR | M10: INVT-COMP | N10: LJU | O10: LJIV | R10: LI03 | S10: POLU | T10: 0 | U10: 79700161 | V10: 2 | W10: 0 | X10: PO_INVT | Y10: 45663 | AD10: PT LEUWITEX | AY10: U/ BAGIAN TRAINING & DEVELOPMENT (HS CODE : 8471.50.90). ERDI
B11: 1 | C11: 10800139 | D11: 4 | E11: 5000005059 | F11: KEYBOARD USB | G11: 1 | H11: BH | I11: 45673 | K11: 95000 | L11: IDR | M11: INVT-COMP | N11: LJU | O11: LJIV | R11: LI03 | S11: POLU | T11: 0 | U11: 79700679 | V11: 1 | W11: 0 | X11: PO_INVT | Y11: 45678 | AD11: PT LEUWITEX | AY11: U/ RUANG MEETING BAGIAN DF LJ1 (HS CODE : 8471.60.30). ERISA
A12: =E12&C12&D12 -> 5000004248108001395 | B12: 2 | C12: 10800139 | D12: 5 | E12: 5000004248 | F12: MOUSE USB | G12: 1 | H12: BH | I12: 45673 | K12: 65000 | L12: IDR | M12: INVT-COMP | N12: LJU | O12: LJIV | R12: LI03 | S12: POLU | T12: 0 | U12: 79700679 | V12: 1 | W12: 0 | X12: PO_INVT | Y12: 45678 | AD12: PT LEUWITEX | AY12: U/ RUANG MEETING BAGIAN DF LJ1 (HS CODE : 8471.60.40). ERISA
A13: =E13&C13&D13 -> 5000013640108001397 | B13: 3 | C13: 10800139 | D13: 7 | E13: 5000013640 | F13: CONNECTOR TELEPHONE | G13: 10 | H13: BH | I13: 45673 | K13: 15000 | L13: IDR | M13: INVT-KTR | N13: LJU | O13: LJIV | R13: LI03 | S13: POLU | T13: 0 | U13: 79700679 | V13: 10 | W13: 0 | X13: PO_INVT | Y13: 45678 | AD13: PT LEUWITEX | AY13: U/ BAGIAN IT, PPC (3), HRD (3), RND DAN MARKETING (2) (HS CODE : 8518.40.20). ERDI
A14: =E14&C14&D14 -> 5000005059108002351 | B14: 4 | C14: 10800235 | D14: 1 | E14: 5000005059 | F14: KEYBOARD USB | G14: 10 | H14: BH | I14: 45679 | K14: 95000 | L14: IDR | M14: INVT-COMP | N14: LJU | O14: LJIV | R14: LI03 | S14: POLU | T14: 0 | U14: 79700679 | V14: 10 | W14: 0 | X14: PO_INVT | Y14: 45678 | AD14: PT LEUWITEX | AY14: U/ BAGIAN QA (2), WEAVING, FINAL, GA, PERSIAPAN LJ3, PPC GREY, MARKETING (2) DAN RND (HS CODE : 8471.60.30). ALI
A15: =E15&C15&D15 -> 5000016541108002711 | B15: 1 | C15: 10800271 | D15: 1 | E15: 5000016541 | F15: FLASH DISK 16 GB | G15: 3 | H15: BH | I15: 45680 | K15: 75000 | L15: IDR | M15: INVT-COMP | N15: LJU | O15: LJIV | R15: LI03 | S15: POLU | T15: 0 | U15: 79700680 | V15: 3 | W15: 0 | X15: PO_INVT | Y15: 45678 | AD15: PT LEUWITEX | AY15: U/ BAGIAN BI : PROYEK BALI, ASURANSI (HS CODE : 8523.29.71). REYZA
A16: =E16&C16&D16 -> 5000005059108001394 | B16: 1 | C16: 10800139 | D16: 4 | E16: 5000005059 | F16: KEYBOARD USB | G16: 1 | H16: BH | I16: 45673 | K16: 95000 | L16: IDR | M16: INVT-COMP | N16: LJU | O16: LJIV | R16: LI03 | S16: POLU | T16: 0 | U16: 79700679 | V16: 1 | W16: 0 | X16: PO_INVT | Y16: 45678 | AD16: PT LEUWITEX | AY16: U/ RUANG MEETING BAGIAN DF LJ1 (HS CODE : 8471.60.30). ERISA
A17: =E17&C17&D17 -> 5000004248108001395 | B17: 2 | C17: 10800139 | D17: 5 | E17: 5000004248 | F17: MOUSE USB | G17: 1 | H17: BH | I17: 45673 | K17: 65000 | L17: IDR | M17: INVT-COMP | N17: LJU | O17: LJIV | R17: LI03 | S17: POLU | T17: 0 | U17: 79700679 | V17: 1 | W17: 0 | X17: PO_INVT | Y17: 45678 | AD17: PT LEUWITEX | AY17: U/ RUANG MEETING BAGIAN DF LJ1 (HS CODE : 8471.60.40). ERISA
A18: =E18&C18&D18 -> 5000013640108001397 | B18: 3 | C18: 10800139 | D18: 7 | E18: 5000013640 | F18: CONNECTOR TELEPHONE | G18: 10 | H18: BH | I18: 45673 | K18: 15000 | L18: IDR | M18: INVT-KTR | N18: LJU | O18: LJIV | R18: LI03 | S18: POLU | T18: 0 | U18: 79700679 | V18: 10 | W18: 0 | X18: PO_INVT | Y18: 45678 | AD18: PT LEUWITEX | AY18: U/ BAGIAN IT, PPC (3), HRD (3), RND DAN MARKETING (2) (HS CODE : 8518.40.20). ERDI
A19: =E19&C19&D19 -> 5000015861108002131 | B19: 1 | C19: 10800213 | D19: 1 | E19: 5000015861 | F19: KAMERA WATERPROOF IP 4MP DAHUA POE | G19: 4 | H19: UNT | I19: 45678 | K19: 1000000 | L19: IDR | M19: INVT-COMP | N19: LJU | O19: LJIV | R19: LI03 | S19: POLU | T19: 0 | U19: 79700733 | V19: 4 | W19: 0 | X19: PO_INVT | Y19: 45678 | AD19: PT LEUWITEX | AY19: U/ AREA GUDANG BARU (BENANG & PACKING) (HS CODE : 8525.81.10). DESSY
A20: =E20&C20&D20 -> 5000015000108002132 | B20: 2 | C20: 10800213 | D20: 2 | E20: 5000015000 | F20: POE INJECTOR | G20: 4 | H20: UNT | I20: 45678 | K20: 350000 | L20: IDR | M20: INVT-COMP | N20: LJU | O20: LJIV | R20: LI03 | S20: POLU | T20: 0 | U20: 79700733 | V20: 4 | W20: 0 | X20: PO_INVT | Y20: 45678 | AD20: PT LEUWITEX | AY20: U/ AREA GUDANG BARU (BENANG & PACKING) (HS CODE : 8517.79.10). DESSY
A21: =E21&C21&D21 -> 5000005059108003092 | B21: 1 | C21: 10800309 | D21: 2 | E21: 5000005059 | F21: KEYBOARD USB | G21: 1 | H21: BH | I21: 45682 | K21: 95000 | L21: IDR | M21: INVT-COMP | N21: LJU | O21: LJIV | R21: LI03 | S21: POLU | T21: 0 | U21: 79700786 | V21: 1 | W21: 0 | X21: PO_INVT | Y21: 45679 | AD21: PT LEUWITEX | AY21: U/ KADEPT HRD OPERASIONAL YANG BARU (HS CODE : 8471.60.30). AYU
A22: =E22&C22&D22 -> 5000004248108003093 | B22: 2 | C22: 10800309 | D22: 3 | E22: 5000004248 | F22: MOUSE USB | G22: 1 | H22: BH | I22: 45682 | K22: 65000 | L22: IDR | M22: INVT-COMP | N22: LJU | O22: LJIV | R22: LI03 | S22: POLU | T22: 0 | U22: 79700786 | V22: 1 | W22: 0 | X22: PO_INVT | Y22: 45679 | AD22: PT LEUWITEX | AY22: U/ KADEPT HRD OPERASIONAL YANG BARU (HS CODE : 8471.60.40). AYU
A23: =E23&C23&D23 -> 5000012021108003095 | B23: 3 | C23: 10800309 | D23: 5 | E23: 5000012021 | F23: KABEL VGA | G23: 1 | H23: BH | I23: 45682 | K23: 30000 | L23: IDR | M23: INVT-COMP | N23: LJU | O23: LJIV | R23: LI03 | S23: POLU | T23: 0 | U23: 79700786 | V23: 1 | W23: 0 | X23: PO_INVT | Y23: 45679 | AD23: PT LEUWITEX | AY23: U/ KADEPT HRD OPERASIONAL YANG BARU (HS CODE : 8544.20.31). AYU
... A41: =E41&C41&D41 -> 5000016428108001396 | B41: 2 | C41: 10800139 | D41: 6 | E41: 5000016428 | F41: PRINTER EPSON L-121 | G41: 1 | H41: UNT | I41: 45673 | K41: 1531532 | L41: IDR | M41: INVT-COMP | N41: LJU | O41: LJIV | R41: LI03 | S41: POLU | T41: 0 | U41: 79700802 | V41: 1 | W41: 0 | X41: PO_INVT | Y41: 45680 | AD41: PT LEUWITEX | AY41: (FP : KB PPN 0%)U/ BAGIAN MTC GREY LJ3 (HS CODE : 8443.31.11). WAHDYAT
A42: =E42&C42&D42 -> 5000017216108003091 | B42: 3 | C42: 10800309 | D42: 1 | E42: 5000017216 | F42: MONITOR LCD 22 INCH | G42: 1 | H42: UNT | I42: 45682 | K42: 1013514 | L42: IDR | M42: INVT-COMP | N42: LJU | O42: LJIV | R42: LI03 | S42: POLU | T42: 0 | U42: 79700802 | V42: 1 | W42: 0 | X42: PO_INVT | Y42: 45680 | Z42: PO_INVT | AA42: 45680 | AD42: PT LEUWITEX | AY42: (FP : KB PPN 0%)U/ KADEPT HRD OPERASIONAL YANG BARU (LENOVO L22E-40)(HS CODE : 8528.52.00). AYU
A43: =E43&C43&D43 -> 5000016728108000971 | B43: 1 | C43: 10800097 | D43: 1 | E43: 5000016728 | F43: SWITCH D-LINK 8 PORT | G43: 1 | H43: UNT | I43: 45671 | K43: 346847 | L43: IDR | M43: INVT-COMP | N43: LJU | O43: LJIV | R43: LI03 | S43: POLU | T43: 0 | U43: 79700803 | V43: 1 | W43: 0 | X43: PO_INVT | Y43: 45680 | AD43: PT LEUWITEX | AY43: (FP : KB PPN 0%) U/ MTC PERSIAPAN LJ2 (HS CODE : 8517.79.10). TIO
A44: =E44&C44&D44 -> 5000016428108004291 | B44: 1 | C44: 10800429 | D44: 1 | E44: 5000016428 | F44: PRINTER EPSON L-121 | G44: 1 | H44: UNT | I44: 45688 | K44: 1531532 | L44: IDR | M44: INVT-COMP | N44: LJU | O44: LJIV | R44: LI03 | S44: POLU | T44: 0 | U44: 79701173 | V44: 1 | W44: 0 | X44: PO_INVT | Y44: 45692 | AD44: PT LEUWITEX | AY44: (FP : KB PPN 0%) U/ PENAMBAHAN DI RUANG BARU BAGIAN UTILITY (HS CODE : 8443.31.11). ERLIN
A45: =E45&C45&D45 -> 5000008843108004501 | B45: 2 | C45: 10800450 | D45: 1 | E45: 5000008843 | F45: MONITOR LCD 19 INCH | G45: 1 | H45: UNT | I45: 45689 | K45: 923424 | L45: IDR | M45: INVT-COMP | N45: LJU | O45: LJIV | R45: LI03 | S45: POLU | T45: 0 | U45: 79701173 | V45: 1 | W45: 0 | X45: PO_INVT | Y45: 45692 | AD45: PT LEUWITEX | AY45: (FP : KB PPN 0%) U/ BAGIAN RND PROCESSING LJ1 (HS CODE : 8528.52.00). TETEN
A46: =E46&C46&D46 -> 5000008843108005371 | B46: 3 | C46: 10800537 | D46: 1 | E46: 5000008843 | F46: MONITOR LCD 19 INCH | G46: 1 | H46: UNT | I46: 45695 | K46: 923424 | L46: IDR | M46: INVT-COMP | N46: LJU | O46: LJIV | R46: LI03 | S46: POLU | T46: 0 | U46: 79701173 | V46: 1 | W46: 0 | X46: PO_INVT | Y46: 45692 | AD46: PT LEUWITEX | AY46: (FP : KB PPN 0%) U/ PIMPINAN PERSIAPAN LJ3 YG BARU (HS CODE : 8528.52.00). DJAFAR
A47: =E47&C47&D47 -> 5000009128108003711 | B47: 1 | C47: 10800371 | D47: 1 | E47: 5000009128 | F47: KABEL POWER SATA | G47: 5 | H47: BH | I47: 45686 | K47: 90000 | L47: IDR | M47: INVT-COMP | N47: LJU | O47: LJIV | R47: LI03 | S47: POLU | T47: 0 | U47: 79701193 | V47: 5 | W47: 0 | X47: PO_INVT | Y47: 45692 | AD47: PT LEUWITEX | AY47: U/ BAGIAN IT (4 PIN)(HS CODE : 8544.20.31). TIO
A48: =E48&C48&D48 -> 5000014667108003713 | B48: 2 | C48: 10800371 | D48: 3 | E48: 5000014667 | F48: ADAPTER 5V | G48: 1 | H48: UNT | I48: 45686 | K48: 70000 | L48: IDR | M48: INVT-COMP | N48: LJU | O48: LJIV | R48: LI03 | S48: POLU | T48: 0 | U48: 79701193 | V48: 1 | W48: 0 | X48: PO_INVT | Y48: 45692 | AD48: PT LEUWITEX | AY48: U/ MENGGANTI YG RUSAK BAGIAN DF LJ1 (HS CODE : 8517.79.10). TIO
A49: =E49&C49&D49 -> 5000016308108004504 | B49: 3 | C49: 10800450 | D49: 4 | E49: 5000016308 | F49: CPU BUILDUP | G49: 1 | H49: UNT | I49: 45689 | K49: 2980000 | L49: IDR | M49: INVT-COMP | N49: LJU | O49: LJIV | R49: LI03 | S49: POLU | T49: 0 | U49: 79701193 | V49: 1 | W49: 0 | X49: PO_INVT | Y49: 45692 | Z49: PO_INVT | AA49: 45692 | AD49: PT LEUWITEX | AY49: U/ BAGIAN RND PROCESSING LJ1 (I5 GEN6) (HS CODE : 8479.89.50). TETEN
A50: =E50&C50&D50 -> 5000016308108005372 | B50: 4 | C50: 10800537 | D50: 2 | E50: 5000016308 | F50: CPU BUILDUP | G50: 1 | H50: UNT | I50: 45695 | K50: 2980000 | L50: IDR | M50: INVT-COMP | N50: LJU | O50: LJIV | R50: LI03 | S50: POLU | T50: 0 | U50: 79701193 | V50: 1 | W50: 0 | X50: PO_INVT | Y50: 45692 | Z50: PO_INVT | AA50: 45692 | AD50: PT LEUWITEX | AY50: U/ PIMPINAN PERSIAPAN LJ3 YG BARU (I5 GEN6) (HS CODE : 8479.89.50). DJAFAR
A51: =E51&C51&D51 -> 5000005340108003712 | B51: 1 | C51: 10800371 | D51: 2 | E51: 5000005340 | F51: POWER SUPLY ATX 450 WATT | G51: 2 | H51: UNT | I51: 45686 | K51: 155000 | L51: IDR | M51: INVT-COMP | N51: LJU | O51: LJIV | R51: LI03 | S51: POLU | T51: 0 | U51: 79701197 | V51: 2 | W51: 0 | X51: PO_INVT | Y51: 45692 | AD51: PT LEUWITEX | AY51: U/ MENGGANTI YG RUSAK BAGIAN PERSONALIA DAN GD PACKING (HS CODE : 8414.59.10). ERDI
A52: =E52&C52&D52 -> 5000014904108004293 | B52: 2 | C52: 10800429 | D52: 3 | E52: 5000014904 | F52: FINGER SCAN SOLUTION X100-C | G52: 1 | H52: UNT | I52: 45689 | K52: 1600000 | L52: IDR | M52: INVT-COMP | N52: LJU | O52: LJIV | R52: LI03 | S52: POLU | T52: 0 | U52: 79701197 | V52: 1 | W52: 0 | X52: PO_INVT | Y52: 45692 | AD52: PT LEUWITEX | AY52: U/ MENGGANTI YANG RUSAK DI AREA EX. PERSONALIA (HS CODE : 8471.90.30). ERIK
A53: =E53&C53&D53 -> 5000005059108004502 | B53: 3 | C53: 10800450 | D53: 2 | E53: 5000005059 | F53: KEYBOARD USB | G53: 1 | H53: BH | I53: 45689 | K53: 95000 | L53: IDR | M53: INVT-COMP | N53: LJU | O53: LJIV | R53: LI03 | S53: POLU | T53: 0 | U53: 79701197 | V53: 1 | W53: 0 | X53: PO_INVT | Y53: 45692 | AD53: PT LEUWITEX | AY53: U/ BAGIAN RND PROCESSING LJ1 (HS CODE : 8471.60.30). TETEN
A54: =E54&C54&D54 -> 5000004248108004503 | B54: 4 | C54: 10800450 | D54: 3 | E54: 5000004248 | F54: MOUSE USB | G54: 3 | H54: BH | I54: 45689 | K54: 65000 | L54: IDR | M54: INVT-COMP | N54: LJU | O54: LJIV | R54: LI03 | S54: POLU | T54: 0 | U54: 79701197 | V54: 3 | W54: 0 | X54: PO_INVT | Y54: 45692 | AD54: PT LEUWITEX | AY54: U/ BAGIAN RND PROCESSING LJ1 DAN MENGGANTI YANG RUSAK BAGIAN KEUANGAN (2) (HS CODE : 8471.60.40). TETEN & FAJAR
A55: =E55&C55&D55 -> 5000012021108004505 | B55: 5 | C55: 10800450 | D55: 5 | E55: 5000012021 | F55: KABEL VGA | G55: 1 | H55: BH | I55: 45689 | K55: 30000 | L55: IDR | M55: INVT-COMP | N55: LJU | O55: LJIV | R55: LI03 | S55: POLU | T55: 0 | U55: 79701197 | V55: 1 | W55: 0 | X55: PO_INVT | Y55: 45692 | AD55: PT LEUWITEX | AY55: U/ BAGIAN RND PROCESSING LJ1 (HS CODE : 8544.20.31). TETEN
A56: =E56&C56&D56 -> 5000016671108004641 | B56: 6 | C56: 10800464 | D56: 1 | E56: 5000016671 | F56: ADAPTER MONITOR 19V | G56: 2 | H56: BH | I56: 45691 | K56: 90000 | L56: IDR | M56: INVT-COMP | N56: LJU | O56: LJIV | R56: LI03 | S56: POLU | T56: 0 | U56: 79701197 | V56: 2 | W56: 0 | X56: PO_INVT | Y56: 45692 | AD56: PT LEUWITEX | AY56: U/ MENGGANTI YANG RUSAK BAGIAN RND DAN KEUANGAN (HS CODE : 8517.79.10). RICKY
A57: =E57&C57&D57 -> 5000015480108004941 | B57: 7 | C57: 10800494 | D57: 1 | E57: 5000015480 | F57: USB TERMINAL | G57: 1 | H57: BH | I57: 45692 | K57: 140000 | L57: IDR | M57: INVT-COMP | N57: LJU | O57: LJIV | R57: LI03 | S57: POLU | T57: 0 | U57: 79701197 | V57: 1 | W57: 0 | X57: PO_INVT | Y57: 45692 | AD57: PT LEUWITEX | AY57: U/ BAGIAN PERSONALIA (HS CODE : 8454.10.00). SARI
...

Sheet GRS 2025
B1: DOC# | C1: DOC_TYPE | D1: POSTING_DATE | E1: FISCAL | F1: ITEM | G1: QTY | H1: EUN | I1: MATERIAL | J1: PLANT | K1: SLOC | L1: BATCH | M1: REFF_NUMBER | N1: MVT | O1: POSTING | P1: STOCK_TYPE | Q1: BUN | R1: AMOUNT | S1: CEK | T1: QTY_EUN | U1: ITEM_REFF | V1: RESERVATION# | W1: POD_SEQ | X1: PHYSICAL# | Y1: CANCEL_DOC | Z1: ITEM_DESC | AA1: BARCODE | AB1: NETTO | AC1: BRUTO | AD1: SEQ_CONTRACT | AE1: AMOUNT_CONTRACT | AF1: AMOUNT_DPP | AG1: ADC | AH1: PPH | AI1: CANCEL_DOC | AJ1: NO_SJ | AK1: NETTO | AL1: BRUTO | AM1: SERVICE | AN1: DISC | AO1: F_TRANS | AP1: KETERANGAN | AQ1: CONTRACT_AMOUNT | AR1: SEQ_CONTRACT | AS1: SUB_VENDOR_CODE | AT1: SUB_VENDOR_NAME | AU1: DOC_STATUS
A2: =I2&M2 -> 500000505979700166 | B2: 5025000485 | C2: WE | D2: 45667 | E2: 2025 | F2: 1 | G2: 2 | I2: 5000005059 | J2: LJU | K2: LJIV | M2: 79700166 | N2: 101 | O2: + | Q2: BH | R2: 190000 | T2: 2 | U2: 1 | Z2: U/ BAGIAN MARKETING (HS CODE : 8471.60.30). ELFHA
A3: =I3&M3 -> 500000424879700166 | B3: 5025000485 | C3: WE | D3: 45667 | E3: 2025 | F3: 2 | G3: 2 | I3: 5000004248 | J3: LJU | K3: LJIV | M3: 79700166 | N3: 101 | O3: + | Q3: BH | R3: 130000 | T3: 2 | U3: 2 | Z3: U/ BAGIAN MARKETING (HS CODE : 8471.60.40). ELFHA
A4: =I4&M4 -> 500001144879700166 | B4: 5025000485 | C4: WE | D4: 45667 | E4: 2025 | F4: 3 | G4: 2 | I4: 5000011448 | J4: LJU | K4: LJIV | M4: 79700166 | N4: 101 | O4: + | Q4: UNT | R4: 100000 | T4: 2 | U4: 3 | Z4: URGENT : ORDER YG 3 METER U/ S. MANAGER PRODUKSI, TEKNIK & HRD DAN PEMBELIAN (HS CODE : 8544.20.31). IDRUS
A5: =I5&M5 -> 500000892979700166 | B5: 5025000485 | C5: WE | D5: 45667 | E5: 2025 | F5: 4 | G5: 6 | I5: 5000008929 | J5: LJU | K5: LJIV | M5: 79700166 | N5: 101 | O5: + | Q5: BH | R5: 900000 | T5: 6 | U5: 4 | Z5: U/ BAGIAN IT (3), FINAL LJU, GD PACKING, PPC PROCESSING LJ1 (HS CODE : 8414.59.10). ERDI
A6: =I6&M6 -> 500001175479700163 | B6: 5025000635 | C6: WE | D6: 45670 | E6: 2025 | F6: 1 | G6: 1 | I6: 5000011754 | J6: LJU | K6: LJIV | M6: 79700163 | N6: 101 | O6: + | Q6: BH | R6: 20000 | T6: 1 | U6: 1 | Z6: U/ S. MANAGER PRODUKSI, TEKNIK & HRD (HS CODE : 8471.60.40). DETA
A7: =I7&M7 -> 500001630879700161 | B7: 5025000984 | C7: WE | D7: 45674 | E7: 2025 | F7: 1 | G7: 2 | I7: 5000016308 | J7: LJU | K7: LJIV | M7: 79700161 | N7: 101 | O7: + | Q7: UNT | R7: 5960000 | T7: 2 | U7: 1 | Z7: U/ BAGIAN MARKETING (HS CODE : 8479.89.50). ELFHA | AB7: 0 | AC7: 0 | AE7: 0
A8: =I8&M8 -> 500001625579700161 | B8: 5025000984 | C8: WE | D8: 45674 | E8: 2025 | F8: 2 | G8: 2 | I8: 5000016255 | J8: LJU | K8: LJIV | M8: 79700161 | N8: 101 | O8: + | Q8: BH | R8: 686000 | T8: 2 | U8: 2 | Z8: U/ BAGIAN TRAINING & DEVELOPMENT (HS CODE : 8471.50.90). ERDI | AB8: 0 | AC8: 0 | AE8: 0
A9: =I9&M9 -> 500001630879700363 | B9: 5025001010 | C9: WE | D9: 45674 | E9: 2025 | F9: 1 | G9: 3 | I9: 5000016308 | J9: LJU | K9: LJIV | M9: 79700363 | N9: 101 | O9: + | Q9: UNT | R9: 8940000 | T9: 3 | U9: 1 | Z9: U/ PROGRAM APLIKASI BARU GD GREY LJ1 (I5 GEN 6) (HS CODE : 8479.89.50). AGUS | AB9: 0 | AC9: 0 | AE9: 0
A10: =I10&M10 -> 500001625579700363 | B10: 5025001010 | C10: WE | D10: 45674 | E10: 2025 | F10: 2 | G10: 2 | I10: 5000016255 | J10: LJU | K10: LJIV | M10: 79700363 | N10: 101 | O10: + | Q10: BH | R10: 686000 | T10: 2 | U10: 2 | Z10: U/ PROGRAM APLIKASI BARU GD GREY LJ1 (HS CODE : 8479.89.50). AGUS | AB10: 0 | AC10: 0 | AE10: 0
A11: =I11&M11 -> 500001586179700733 | B11: 5025001652 | C11: WE | D11: 45684 | E11: 2025 | F11: 1 | G11: 4 | I11: 5000015861 | J11: LJU | K11: LJIV | M11: 79700733 | N11: 101 | O11: + | Q11: UNT | R11: 4000000 | T11: 4 | U11: 1 | Z11: U/ AREA GUDANG BARU (BENANG & PACKING) (HS CODE : 8525.81.10). DESSY
A12: =I12&M12 -> 500001500079700733 | B12: 5025001652 | C12: WE | D12: 45684 | E12: 2025 | F12: 2 | G12: 4 | I12: 5000015000 | J12: LJU | K12: LJIV | M12: 79700733 | N12: 101 | O12: + | Q12: UNT | R12: 1400000 | T12: 4 | U12: 2 | Z12: U/ AREA GUDANG BARU (BENANG & PACKING) (HS CODE : 8517.79.10). DESSY
A13: =I13&M13 -> 500001672879700803 | B13: 5025001655 | C13: WE | D13: 45684 | E13: 2025 | F13: 1 | G13: 1 | I13: 5000016728 | J13: LJU | K13: LJIV | M13: 79700803 | N13: 101 | O13: + | Q13: UNT | R13: 346847 | T13: 1 | U13: 1 | Z13: (FP : KB PPN 0%) U/ MTC PERSIAPAN LJ2 (HS CODE : 8517.79.10). TIO | AB13: 0 | AC13: 0 | AE13: 0
A14: =I14&M14 -> 500001654179700680 | B14: 5025001688 | C14: WE | D14: 45684 | E14: 2025 | F14: 1 | G14: 3 | I14: 5000016541 | J14: LJU | K14: LJIV | M14: 79700680 | N14: 101 | O14: + | Q14: BH | R14: 225000 | T14: 3 | U14: 1 | Z14: U/ BAGIAN BI : PROYEK BALI, ASURANSI (HS CODE : 8523.29.71). REYZA
A15: =I15&M15 -> 500000505979700786 | B15: 5025001719 | C15: WE | D15: 45685 | E15: 2025 | F15: 1 | G15: 1 | I15: 5000005059 | J15: LJU | K15: LJIV | M15: 79700786 | N15: 101 | O15: + | Q15: BH | R15: 95000 | T15: 1 | U15: 1 | Z15: U/ KADEPT HRD OPERASIONAL YANG BARU (HS CODE : 8471.60.30). AYU
A16: =I16&M16 -> 500000424879700786 | B16: 5025001719 | C16: WE | D16: 45685 | E16: 2025 | F16: 2 | G16: 1 | I16: 5000004248 | J16: LJU | K16: LJIV | M16: 79700786 | N16: 101 | O16: + | Q16: BH | R16: 65000 | T16: 1 | U16: 2 | Z16: U/ KADEPT HRD OPERASIONAL YANG BARU (HS CODE : 8471.60.40). AYU
A17: =I17&M17 -> 500001202179700786 | B17: 5025001719 | C17: WE | D17: 45685 | E17: 2025 | F17: 3 | G17: 1 | I17: 5000012021 | J17: LJU | K17: LJIV | M17: 79700786 | N17: 101 | O17: + | Q17: BH | R17: 30000 | T17: 1 | U17: 3 | Z17: U/ KADEPT HRD OPERASIONAL YANG BARU (HS CODE : 8544.20.31). AYU
A18: =I18&M18 -> 500001175479700786 | B18: 5025001719 | C18: WE | D18: 45685 | E18: 2025 | F18: 4 | G18: 2 | I18: 5000011754 | J18: LJU | K18: LJIV | M18: 79700786 | N18: 101 | O18: + | Q18: BH | R18: 40000 | T18: 2 | U18: 4 | Z18: U/ KADEPT HRD OPERASIONAL YANG BARU & BAGIAN BEACUKAI (HS CODE : 8471.60.40). AYU & PUTRI
A19: =I19&M19 -> 500000884379700802 | B19: 5025001725 | C19: WE | D19: 45685 | E19: 2025 | F19: 1 | G19: 1 | I19: 5000008843 | J19: LJU | K19: LJIV | M19: 79700802 | N19: 101 | O19: + | Q19: UNT | R19: 923424 | T19: 1 | U19: 1 | Z19: (FP : KB PPN 0%) U/ RUANG MEETING BAGIAN DF LJ1 (HS CODE : 8528.52.00). ERISA | AB19: 0 | AC19: 0 | AE19: 0
A20: =I20&M20 -> 500001642879700802 | B20: 5025001725 | C20: WE | D20: 45685 | E20: 2025 | F20: 2 | G20: 1 | I20: 5000016428 | J20: LJU | K20: LJIV | M20: 79700802 | N20: 101 | O20: + | Q20: UNT | R20: 1531532 | T20: 1 | U20: 2 | Z20: (FP : KB PPN 0%)U/ BAGIAN MTC GREY LJ3 (HS CODE : 8443.31.11). WAHDYAT | AB20: 0 | AC20: 0 | AE20: 0
A21: =I21&M21 -> 500001721679700802 | B21: 5025001725 | C21: WE | D21: 45685 | E21: 2025 | F21: 3 | G21: 1 | I21: 5000017216 | J21: LJU | K21: LJIV | M21: 79700802 | N21: 101 | O21: + | Q21: UNT | R21: 1013514 | T21: 1 | U21: 3 | Z21: (FP : KB PPN 0%)U/ KADEPT HRD OPERASIONAL YANG BARU (LENOVO L22E-40)(HS CODE : 8528.52.00). AYU | AB21: 0 | AC21: 0 | AE21: 0
A22: =I22&M22 -> 500001735679700788 | B22: 5025001853 | C22: WE | D22: 45687 | E22: 2025 | F22: 1 | G22: 1 | I22: 5000017356 | J22: LJU | K22: LJIV | M22: 79700788 | N22: 101 | O22: + | Q22: UNT | R22: 4875000 | T22: 1 | U22: 1 | Z22: U/ RUANG MEETING BAGIAN DF LJ1 (HS CODE : 9007.92.00). ERISA | AB22: 0 | AC22: 0 | AE22: 0
A23: =I23&M23 -> 500001630879700788 | B23: 5025001853 | C23: WE | D23: 45687 | E23: 2025 | F23: 2 | G23: 1 | I23: 5000016308 | J23: LJU | K23: LJIV | M23: 79700788 | N23: 101 | O23: + | Q23: UNT | R23: 2980000 | T23: 1 | U23: 2 | Z23: U/ RUANG MEETING BAGIAN DF LJ1 (I5 GEN 6)(HS CODE : 8479.89.50). ERISA | AB23: 0 | AC23: 0 | AE23: 0
A24: =I24&M24 -> 500001630879700788 | B24: 5025001853 | C24: WE | D24: 45687 | E24: 2025 | F24: 3 | G24: 1 | I24: 5000016308 | J24: LJU | K24: LJIV | M24: 79700788 | N24: 101 | O24: + | Q24: UNT | R24: 2980000 | T24: 1 | U24: 3 | Z24: U/ KADEPT HRD OPERASIONAL YANG BARU (I5 GEN 6)(HS CODE : 8479.89.50). AYU | AB24: 0 | AC24: 0 | AE24: 0
A25: =I25&M25 -> 500001618579700788 | B25: 5025001853 | C25: WE | D25: 45687 | E25: 2025 | F25: 4 | G25: 1 | I25: 5000016185 | J25: LJU | K25: LJIV | M25: 79700788 | N25: 101 | O25: + | Q25: BH | R25: 1625000 | T25: 1 | U25: 4 | Z25: U/ KADEPT HRD OPERASIONAL YANG BARU (PANASONIC KX DT -521) (HS CODE : 8517.14.00). AYU | AB25: 0 | AC25: 0 | AE25: 0
A26: =I26&M26 -> 500000505979700679 | B26: 5025001921 | C26: WE | D26: 45688 | E26: 2025 | F26: 1 | G26: 1 | I26: 5000005059 | J26: LJU | K26: LJIV | M26: 79700679 | N26: 101 | O26: + | Q26: BH | R26: 95000 | T26: 1 | U26: 1 | Z26: U/ RUANG MEETING BAGIAN DF LJ1 (HS CODE : 8471.60.30). ERISA
A27: =I27&M27 -> 500000424879700679 | B27: 5025001921 | C27: WE | D27: 45688 | E27: 2025 | F27: 2 | G27: 1 | I27: 5000004248 | J27: LJU | K27: LJIV | M27: 79700679 | N27: 101 | O27: + | Q27: BH | R27: 65000 | T27: 1 | U27: 2 | Z27: U/ RUANG MEETING BAGIAN DF LJ1 (HS CODE : 8471.60.40). ERISA
A28: =I28&M28 -> 500001364079700679 | B28: 5025001921 | C28: WE | D28: 45688 | E28: 2025 | F28: 3 | G28: 10 | I28: 5000013640 | J28: LJU | K28: LJIV | M28: 79700679 | N28: 101 | O28: + | Q28: BH | R28: 150000 | T28: 10 | U28: 3 | Z28: U/ BAGIAN IT, PPC (3), HRD (3), RND DAN MARKETING (2) (HS CODE : 8518.40.20). ERDI
A29: =I29&M29 -> 500000505979700679 | B29: 5025001921 | C29: WE | D29: 45688 | E29: 2025 | F29: 4 | G29: 10 | I29: 5000005059 | J29: LJU | K29: LJIV | M29: 79700679 | N29: 101 | O29: + | Q29: BH | R29: 950000 | T29: 10 | U29: 4 | Z29: U/ BAGIAN QA (2), WEAVING, FINAL, GA, PERSIAPAN LJ3, PPC GREY, MARKETING (2) DAN RND (HS CODE : 8471.60.30). ALI
A30: =I30&M30 -> 500000534079701197 | B30: 5025002538 | C30: WE | D30: 45699 | E30: 2025 | F30: 1 | G30: 2 | I30: 5000005340 | J30: LJU | K30: LJIV | M30: 79701197 | N30: 101 | O30: + | Q30: UNT | R30: 310000 | T30: 2 | U30: 1 | Z30: U/ MENGGANTI YG RUSAK BAGIAN PERSONALIA DAN GD PACKING (HS CODE : 8414.59.10). ERDI
A31: =I31&M31 -> 500001490479701197 | B31: 5025002538 | C31: WE | D31: 45699 | E31: 2025 | F31: 2 | G31: 1 | I31: 5000014904 | J31: LJU | K31: LJIV | M31: 79701197 | N31: 101 | O31: + | Q31: UNT | R31: 1600000 | T31: 1 | U31: 2 | Z31: U/ MENGGANTI YANG RUSAK DI AREA EX. PERSONALIA (HS CODE : 8471.90.30). ERIK
A32: =I32&M32 -> 500000505979701197 | B32: 5025002538 | C32: WE | D32: 45699 | E32: 2025 | F32: 3 | G32: 1 | I32: 5000005059 | J32: LJU | K32: LJIV | M32: 79701197 | N32: 101 | O32: + | Q32: BH | R32: 95000 | T32: 1 | U32: 3 | Z32: U/ BAGIAN RND PROCESSING LJ1 (HS CODE : 8471.60.30). TETEN
A33: =I33&M33 -> 500000424879701197 | B33: 5025002538 | C33: WE | D33: 45699 | E33: 2025 | F33: 4 | G33: 3 | I33: 5000004248 | J33: LJU | K33: LJIV | M33: 79701197 | N33: 101 | O33: + | Q33: BH | R33: 195000 | T33: 3 | U33: 4 | Z33: U/ BAGIAN RND PROCESSING LJ1 DAN MENGGANTI YANG RUSAK BAGIAN KEUANGAN (2) (HS CODE : 8471.60.40). TETEN & FAJAR
A34: =I34&M34 -> 500001202179701197 | B34: 5025002538 | C34: WE | D34: 45699 | E34: 2025 | F34: 5 | G34: 1 | I34: 5000012021 | J34: LJU | K34: LJIV | M34: 79701197 | N34: 101 | O34: + | Q34: BH | R34: 30000 | T34: 1 | U34: 5 | Z34: U/ BAGIAN RND PROCESSING LJ1 (HS CODE : 8544.20.31). TETEN
A35: =I35&M35 -> 500001667179701197 | B35: 5025002538 | C35: WE | D35: 45699 | E35: 2025 | F35: 6 | G35: 2 | I35: 5000016671 | J35: LJU | K35: LJIV | M35: 79701197 | N35: 101 | O35: + | Q35: BH | R35: 180000 | T35: 2 | U35: 6 | Z35: U/ MENGGANTI YANG RUSAK BAGIAN RND DAN KEUANGAN (HS CODE : 8517.79.10). RICKY
A36: =I36&M36 -> 500001548079701197 | B36: 5025002538 | C36: WE | D36: 45699 | E36: 2025 | F36: 7 | G36: 1 | I36: 5000015480 | J36: LJU | K36: LJIV | M36: 79701197 | N36: 101 | O36: + | Q36: BH | R36: 140000 | T36: 1 | U36: 7 | Z36: U/ BAGIAN PERSONALIA (HS CODE : 8454.10.00). SARI
A37: =I37&M37 -> 500000505979701197 | B37: 5025002538 | C37: WE | D37: 45699 | E37: 2025 | F37: 8 | G37: 1 | I37: 5000005059 | J37: LJU | K37: LJIV | M37: 79701197 | N37: 101 | O37: + | Q37: BH | R37: 95000 | T37: 1 | U37: 8 | Z37: U/ PIMPINAN PERSIAPAN LJ3 YG BARU (HS CODE : 8471.60.30). DJAFAR
... A42: =I42&M42 -> 500000884379701173 | B42: 5025002541 | C42: WE | D42: 45699 | E42: 2025 | F42: 3 | G42: 1 | I42: 5000008843 | J42: LJU | K42: LJIV | M42: 79701173 | N42: 101 | O42: + | Q42: UNT | R42: 923424 | T42: 1 | U42: 3 | Z42: (FP : KB PPN 0%) U/ PIMPINAN PERSIAPAN LJ3 YG BARU (HS CODE : 8528.52.00). DJAFAR
A43: =I43&M43 -> 500001710579701495 | B43: 5025003221 | C43: WE | D43: 45708 | E43: 2025 | F43: 1 | G43: 2 | I43: 5000017105 | J43: LJU | K43: LJIV | M43: 79701495 | N43: 101 | O43: + | Q43: UNT | R43: 1081082 | T43: 2 | U43: 1 | Z43: (FP : KB PPN 0%) ORDER 100 PAIR U/ PROJECT GEDUNG MARKETING YG BARU (HS CODE : 8536.90.93).TIO | AB43: 0 | AC43: 0 | AE43: 0
A44: =I44&M44 -> 500001710579701495 | B44: 5025003221 | C44: WE | D44: 45708 | E44: 2025 | F44: 2 | G44: 1 | I44: 5000017105 | J44: LJU | K44: LJIV | M44: 79701495 | N44: 101 | O44: + | Q44: UNT | R44: 1036036.1 | T44: 1 | U44: 2 | Z44: (FP : KB PPN 0%) ORDER 200 PAIR U/ PROJECT GEDUNG MARKETING YG BARU (HS CODE : 8536.90.93).TIO | AB44: 0 | AC44: 0 | AE44: 0
...

Sheet MATERIAL DISCONTINUE
A1: No | B1: No Material Lama | C1: Nama Material Lama | D1: No Material Baru | E1: Nama Material Baru | F1: Satuan | G1: Keterangan
A2: 1 | B2: 5000015934 | C2: PRINTER EPSON L 3110 | D2: 5000016375 | E2: PRINTER EPSON l3210 | F2: UNT
A3: 2 | C3: RAM DDR2 | G3: Hanya ada yg 2GB karena susah barangnya
A4: 3 | B4: 5000016371 | C4: SYNOLOGY DS-220J | D4: 5000017680 | E4: SYNOLOGY DS-223J | F4: UNT

Sheet Sheet1
L5: 10801360 | N5: 10801360 | O5: 10801580 | P5: 10801842 | Q5: 10803362 | R5: 10805458 | S5: 10805511 | T5: 10805529 | U5: 10805549
L6: 10801580
L7: 10801842
L8: 10803362
L9: 10805458
L10: 10805511
L11: 10805529
L12: 10805549
L14: 79704819
L15: 79710865 | N15: 79704819 | O15: 79710865 | P15: 79711295 | Q15: 79711830 | R15: 79711832 | S15: 79711831
L16: 79711295
L17: 79711830
L18: 79711832
L19: 79711831
L23: 10801360 | N23: 10801360 | O23: 10801580 | P23: 10801842 | Q23: 10803362 | R23: 10805549 | S23: 10805600
L24: 10801580
L25: 10801842
L26: 10803362
L27: 10805549
L28: 10805600
L31: 79704819 | N31: 79704819 | O31: 79711295 | P31: 79711830 | Q31: 79711832 | R31: 79711831
L32: 79711295
L33: 79711830
L34: 79711832
L35: 79711831
